[32m2024-07-10 11:40:57 +0300[0m - dagster - [34mDEBUG[0m - adhoc_request_job - 27d56603-4527-40b0-8cad-1db25d433b32 - 69063 - LOGS_CAPTURED - Started capturing logs in process (pid: 69063).
[32m2024-07-10 11:40:57 +0300[0m - dagster - [34mDEBUG[0m - adhoc_request_job - 27d56603-4527-40b0-8cad-1db25d433b32 - 69063 - adhoc_request - STEP_START - Started execution of step "adhoc_request".
[32m2024-07-10 11:42:40 +0300[0m - dagster - [34mERROR[0m - [31madhoc_request_job - 27d56603-4527-40b0-8cad-1db25d433b32 - 69063 - adhoc_request - STEP_FAILURE - Execution of step "adhoc_request" failed.

dagster._core.errors.DagsterExecutionStepExecutionError: Error occurred while executing op "adhoc_request"::

duckdb.duckdb.IOException: IO Error: Could not set lock on file "/Users/abdulrahman/Documents/Dagster/dagster_university/data/staging/data.duckdb": Conflicting lock is held in /Applications/DBeaver.app/Contents/MacOS/dbeaver (PID 37062) by user abdulrahman. See also https://duckdb.org/docs/connect/concurrency

Stack Trace:
  File "/Users/abdulrahman/Documents/Dagster/venv/lib/python3.11/site-packages/dagster/_core/execution/plan/utils.py", line 54, in op_execution_error_boundary
    yield
  File "/Users/abdulrahman/Documents/Dagster/venv/lib/python3.11/site-packages/dagster/_utils/__init__.py", line 468, in iterate_with_context
    next_output = next(iterator)
                  ^^^^^^^^^^^^^^
  File "/Users/abdulrahman/Documents/Dagster/venv/lib/python3.11/site-packages/dagster/_core/execution/plan/compute_generator.py", line 141, in _coerce_op_compute_fn_to_iterator
    result = invoke_compute_fn(
             ^^^^^^^^^^^^^^^^^^
  File "/Users/abdulrahman/Documents/Dagster/venv/lib/python3.11/site-packages/dagster/_core/execution/plan/compute_generator.py", line 129, in invoke_compute_fn
    return fn(context, **args_to_pass) if context_arg_provided else fn(**args_to_pass)
                                                                    ^^^^^^^^^^^^^^^^^^
  File "/Users/abdulrahman/Documents/Dagster/dagster_university/dagster_university/assets/requests.py", line 48, in adhoc_request
    with database.get_connection() as conn:
  File "/Library/Frameworks/Python.framework/Versions/3.11/lib/python3.11/contextlib.py", line 137, in __enter__
    return next(self.gen)
           ^^^^^^^^^^^^^^
  File "/Users/abdulrahman/Documents/Dagster/venv/lib/python3.11/site-packages/dagster_duckdb/resource.py", line 51, in get_connection
    conn = backoff(
           ^^^^^^^^
  File "/Users/abdulrahman/Documents/Dagster/venv/lib/python3.11/site-packages/dagster/_utils/backoff.py", line 70, in backoff
    raise to_raise
  File "/Users/abdulrahman/Documents/Dagster/venv/lib/python3.11/site-packages/dagster/_utils/backoff.py", line 64, in backoff
    return fn(*args, **kwargs)
           ^^^^^^^^^^^^^^^^^^^
[0m
