[32m2024-07-04 11:11:35 +0300[0m - dagster - [34mDEBUG[0m - __ASSET_JOB - ef0de2d0-3a2c-4f60-9365-af4ef1d15040 - 20027 - LOGS_CAPTURED - Started capturing logs in process (pid: 20027).
[32m2024-07-04 11:11:35 +0300[0m - dagster - [34mDEBUG[0m - __ASSET_JOB - ef0de2d0-3a2c-4f60-9365-af4ef1d15040 - 20027 - taxi_zones_file - STEP_START - Started execution of step "taxi_zones_file".
[32m2024-07-04 11:11:41 +0300[0m - dagster - [34mERROR[0m - [31m__ASSET_JOB - ef0de2d0-3a2c-4f60-9365-af4ef1d15040 - 20027 - taxi_zones_file - STEP_FAILURE - Execution of step "taxi_zones_file" failed.

dagster._core.errors.DagsterExecutionStepExecutionError: Error occurred while executing op "taxi_zones_file"::

NameError: name 'raw_trips' is not defined

Stack Trace:
  File "/Users/abdulrahman/Documents/Dagster/venv/lib/python3.11/site-packages/dagster/_core/execution/plan/utils.py", line 54, in op_execution_error_boundary
    yield
  File "/Users/abdulrahman/Documents/Dagster/venv/lib/python3.11/site-packages/dagster/_utils/__init__.py", line 468, in iterate_with_context
    next_output = next(iterator)
                  ^^^^^^^^^^^^^^
  File "/Users/abdulrahman/Documents/Dagster/venv/lib/python3.11/site-packages/dagster/_core/execution/plan/compute_generator.py", line 141, in _coerce_op_compute_fn_to_iterator
    result = invoke_compute_fn(
             ^^^^^^^^^^^^^^^^^^
  File "/Users/abdulrahman/Documents/Dagster/venv/lib/python3.11/site-packages/dagster/_core/execution/plan/compute_generator.py", line 129, in invoke_compute_fn
    return fn(context, **args_to_pass) if context_arg_provided else fn(**args_to_pass)
                                                                    ^^^^^^^^^^^^^^^^^^
  File "/Users/abdulrahman/Documents/Dagster/dagster_university/dagster_university/assets/trips.py", line 23, in taxi_zones_file
    output_file.write(raw_trips.content)
                      ^^^^^^^^^
[0m
