[32m2024-07-07 15:33:12 +0300[0m - dagster - [34mDEBUG[0m - __ASSET_JOB - 0ddd2060-470b-4396-af7d-a71fbea8c14a - 37639 - LOGS_CAPTURED - Started capturing logs in process (pid: 37639).
[32m2024-07-07 15:33:12 +0300[0m - dagster - [34mDEBUG[0m - __ASSET_JOB - 0ddd2060-470b-4396-af7d-a71fbea8c14a - 37639 - trips_by_week2 - STEP_START - Started execution of step "trips_by_week2".
[32m2024-07-07 15:33:12 +0300[0m - dagster - [34mERROR[0m - [31m__ASSET_JOB - 0ddd2060-470b-4396-af7d-a71fbea8c14a - 37639 - trips_by_week2 - STEP_FAILURE - Execution of step "trips_by_week2" failed.

dagster._core.errors.DagsterExecutionStepExecutionError: Error occurred while executing op "trips_by_week2"::

NameError: name 'datetime' is not defined

Stack Trace:
  File "/Users/abdulrahman/Documents/Dagster/venv/lib/python3.11/site-packages/dagster/_core/execution/plan/utils.py", line 54, in op_execution_error_boundary
    yield
  File "/Users/abdulrahman/Documents/Dagster/venv/lib/python3.11/site-packages/dagster/_utils/__init__.py", line 468, in iterate_with_context
    next_output = next(iterator)
                  ^^^^^^^^^^^^^^
  File "/Users/abdulrahman/Documents/Dagster/venv/lib/python3.11/site-packages/dagster/_core/execution/plan/compute_generator.py", line 141, in _coerce_op_compute_fn_to_iterator
    result = invoke_compute_fn(
             ^^^^^^^^^^^^^^^^^^
  File "/Users/abdulrahman/Documents/Dagster/venv/lib/python3.11/site-packages/dagster/_core/execution/plan/compute_generator.py", line 129, in invoke_compute_fn
    return fn(context, **args_to_pass) if context_arg_provided else fn(**args_to_pass)
                                                                    ^^^^^^^^^^^^^^^^^^
  File "/Users/abdulrahman/Documents/Dagster/dagster_university/dagster_university/assets/metrics.py", line 82, in trips_by_week2
    current_date = datetime.strptime("2023-03-01", constants.DATE_FORMAT)
                   ^^^^^^^^
[0m
